ERROR:cassandra.datastax.cloud:HTTP Error 401: Unauthorized
Traceback (most recent call last):
  File "/Users/aakash/anaconda3/lib/python3.10/site-packages/cassandra/datastax/cloud/__init__.py", line 138, in read_metadata_info
    response = urlopen(url, context=config.ssl_context, timeout=timeout)
  File "/Users/aakash/anaconda3/lib/python3.10/urllib/request.py", line 216, in urlopen
    return opener.open(url, data, timeout)
  File "/Users/aakash/anaconda3/lib/python3.10/urllib/request.py", line 525, in open
    response = meth(req, response)
  File "/Users/aakash/anaconda3/lib/python3.10/urllib/request.py", line 634, in http_response
    response = self.parent.error(
  File "/Users/aakash/anaconda3/lib/python3.10/urllib/request.py", line 563, in error
    return self._call_chain(*args)
  File "/Users/aakash/anaconda3/lib/python3.10/urllib/request.py", line 496, in _call_chain
    result = func(*args)
  File "/Users/aakash/anaconda3/lib/python3.10/urllib/request.py", line 643, in http_error_default
    raise HTTPError(req.full_url, code, msg, hdrs, fp)
urllib.error.HTTPError: HTTP Error 401: Unauthorized
ERROR:root:An unexpected error occurred: Unable to connect to the metadata service at https://8b90d1e6-1af1-435b-89b6-ce428cc0d251-us-east1.db.astra.datastax.com:29080/metadata. Check the cluster status in the cloud console. 
ERROR:cassandra.datastax.cloud:HTTP Error 401: Unauthorized
Traceback (most recent call last):
  File "/Users/aakash/anaconda3/lib/python3.10/site-packages/cassandra/datastax/cloud/__init__.py", line 138, in read_metadata_info
    response = urlopen(url, context=config.ssl_context, timeout=timeout)
  File "/Users/aakash/anaconda3/lib/python3.10/urllib/request.py", line 216, in urlopen
    return opener.open(url, data, timeout)
  File "/Users/aakash/anaconda3/lib/python3.10/urllib/request.py", line 525, in open
    response = meth(req, response)
  File "/Users/aakash/anaconda3/lib/python3.10/urllib/request.py", line 634, in http_response
    response = self.parent.error(
  File "/Users/aakash/anaconda3/lib/python3.10/urllib/request.py", line 563, in error
    return self._call_chain(*args)
  File "/Users/aakash/anaconda3/lib/python3.10/urllib/request.py", line 496, in _call_chain
    result = func(*args)
  File "/Users/aakash/anaconda3/lib/python3.10/urllib/request.py", line 643, in http_error_default
    raise HTTPError(req.full_url, code, msg, hdrs, fp)
urllib.error.HTTPError: HTTP Error 401: Unauthorized
ERROR:root:An unexpected error occurred: Unable to connect to the metadata service at https://8b90d1e6-1af1-435b-89b6-ce428cc0d251-us-east1.db.astra.datastax.com:29080/metadata. Check the cluster status in the cloud console. 
ERROR:cassandra.connection:Closing connection <AsyncoreConnection(4897027456) 8b90d1e6-1af1-435b-89b6-ce428cc0d251-us-east1.db.astra.datastax.com:29042:734aff59-e842-4de3-b5d9-7d7938c90a60> due to protocol error: Error from server: code=000a [Protocol error] message="Beta version of the protocol used (5/v5-beta), but USE_BETA flag is unset"
